[2023-12-19T17:47:01.031+0000] {taskinstance.py:1957} INFO - Dependencies all met for dep_context=non-requeueable deps ti=<TaskInstance: load_data.load_data_task_one scheduled__2023-12-19T17:46:00+00:00 [queued]>
[2023-12-19T17:47:01.044+0000] {taskinstance.py:1957} INFO - Dependencies all met for dep_context=requeueable deps ti=<TaskInstance: load_data.load_data_task_one scheduled__2023-12-19T17:46:00+00:00 [queued]>
[2023-12-19T17:47:01.045+0000] {taskinstance.py:2171} INFO - Starting attempt 1 of 2
[2023-12-19T17:47:01.073+0000] {taskinstance.py:2192} INFO - Executing <Task(PythonOperator): load_data_task_one> on 2023-12-19 17:46:00+00:00
[2023-12-19T17:47:01.081+0000] {standard_task_runner.py:60} INFO - Started process 244 to run task
[2023-12-19T17:47:01.085+0000] {standard_task_runner.py:87} INFO - Running: ['***', 'tasks', 'run', 'load_data', 'load_data_task_one', 'scheduled__2023-12-19T17:46:00+00:00', '--job-id', '65', '--raw', '--subdir', 'DAGS_FOLDER/load_data_dag.py', '--cfg-path', '/tmp/tmpsf1kgulo']
[2023-12-19T17:47:01.089+0000] {standard_task_runner.py:88} INFO - Job 65: Subtask load_data_task_one
[2023-12-19T17:47:01.152+0000] {task_command.py:423} INFO - Running <TaskInstance: load_data.load_data_task_one scheduled__2023-12-19T17:46:00+00:00 [running]> on host adf250ae6131
[2023-12-19T17:47:01.425+0000] {taskinstance.py:2481} INFO - Exporting env vars: AIRFLOW_CTX_DAG_OWNER='Mickiyas' AIRFLOW_CTX_DAG_ID='load_data' AIRFLOW_CTX_TASK_ID='load_data_task_one' AIRFLOW_CTX_EXECUTION_DATE='2023-12-19T17:46:00+00:00' AIRFLOW_CTX_TRY_NUMBER='1' AIRFLOW_CTX_DAG_RUN_ID='scheduled__2023-12-19T17:46:00+00:00'
[2023-12-19T17:47:01.429+0000] {taskinstance.py:2699} ERROR - Task failed with exception
Traceback (most recent call last):
  File "/home/airflow/.local/lib/python3.8/site-packages/airflow/models/taskinstance.py", line 433, in _execute_task
    result = execute_callable(context=context, **execute_callable_kwargs)
  File "/home/airflow/.local/lib/python3.8/site-packages/airflow/operators/python.py", line 199, in execute
    return_value = self.execute_callable()
  File "/home/airflow/.local/lib/python3.8/site-packages/airflow/operators/python.py", line 216, in execute_callable
    return self.python_callable(*self.op_args, **self.op_kwargs)
  File "/opt/airflow/dags/load_data_dag.py", line 17, in load_data
    df = pd.read_csv(file_path)
  File "/home/airflow/.local/lib/python3.8/site-packages/pandas/io/parsers/readers.py", line 912, in read_csv
    return _read(filepath_or_buffer, kwds)
  File "/home/airflow/.local/lib/python3.8/site-packages/pandas/io/parsers/readers.py", line 577, in _read
    parser = TextFileReader(filepath_or_buffer, **kwds)
  File "/home/airflow/.local/lib/python3.8/site-packages/pandas/io/parsers/readers.py", line 1407, in __init__
    self._engine = self._make_engine(f, self.engine)
  File "/home/airflow/.local/lib/python3.8/site-packages/pandas/io/parsers/readers.py", line 1661, in _make_engine
    self.handles = get_handle(
  File "/home/airflow/.local/lib/python3.8/site-packages/pandas/io/common.py", line 859, in get_handle
    handle = open(
FileNotFoundError: [Errno 2] No such file or directory: '../raw-data/20181024_d1_0830_0900.csv'
[2023-12-19T17:47:01.440+0000] {taskinstance.py:1138} INFO - Marking task as UP_FOR_RETRY. dag_id=load_data, task_id=load_data_task_one, execution_date=20231219T174600, start_date=20231219T174701, end_date=20231219T174701
[2023-12-19T17:47:01.458+0000] {standard_task_runner.py:107} ERROR - Failed to execute job 65 for task load_data_task_one ([Errno 2] No such file or directory: '../raw-data/20181024_d1_0830_0900.csv'; 244)
[2023-12-19T17:47:01.501+0000] {local_task_job_runner.py:234} INFO - Task exited with return code 1
[2023-12-19T17:47:01.518+0000] {taskinstance.py:3281} INFO - 0 downstream tasks scheduled from follow-on schedule check
