[2023-12-23T13:40:51.351+0000] {taskinstance.py:1957} INFO - Dependencies all met for dep_context=non-requeueable deps ti=<TaskInstance: dag_to_dum_raw_data_to_postgres.load_raw_data_to_postgres manual__2023-12-23T13:40:48.232288+00:00 [queued]>
[2023-12-23T13:40:51.365+0000] {taskinstance.py:1957} INFO - Dependencies all met for dep_context=requeueable deps ti=<TaskInstance: dag_to_dum_raw_data_to_postgres.load_raw_data_to_postgres manual__2023-12-23T13:40:48.232288+00:00 [queued]>
[2023-12-23T13:40:51.366+0000] {taskinstance.py:2171} INFO - Starting attempt 1 of 6
[2023-12-23T13:40:51.515+0000] {taskinstance.py:2192} INFO - Executing <Task(PythonOperator): load_raw_data_to_postgres> on 2023-12-23 13:40:48.232288+00:00
[2023-12-23T13:40:51.521+0000] {standard_task_runner.py:60} INFO - Started process 289 to run task
[2023-12-23T13:40:51.525+0000] {standard_task_runner.py:87} INFO - Running: ['***', 'tasks', 'run', 'dag_to_dum_raw_data_to_postgres', 'load_raw_data_to_postgres', 'manual__2023-12-23T13:40:48.232288+00:00', '--job-id', '1224', '--raw', '--subdir', 'DAGS_FOLDER/dump_raw_data_to_postgres.py', '--cfg-path', '/tmp/tmph7siwbxq']
[2023-12-23T13:40:51.529+0000] {standard_task_runner.py:88} INFO - Job 1224: Subtask load_raw_data_to_postgres
[2023-12-23T13:40:51.584+0000] {task_command.py:423} INFO - Running <TaskInstance: dag_to_dum_raw_data_to_postgres.load_raw_data_to_postgres manual__2023-12-23T13:40:48.232288+00:00 [running]> on host 51dca2e3ed8e
[2023-12-23T13:40:51.687+0000] {taskinstance.py:2481} INFO - Exporting env vars: AIRFLOW_CTX_DAG_OWNER='10 academy' AIRFLOW_CTX_DAG_ID='dag_to_dum_raw_data_to_postgres' AIRFLOW_CTX_TASK_ID='load_raw_data_to_postgres' AIRFLOW_CTX_EXECUTION_DATE='2023-12-23T13:40:48.232288+00:00' AIRFLOW_CTX_TRY_NUMBER='1' AIRFLOW_CTX_DAG_RUN_ID='manual__2023-12-23T13:40:48.232288+00:00'
[2023-12-23T13:40:51.689+0000] {taskinstance.py:2699} ERROR - Task failed with exception
Traceback (most recent call last):
  File "/home/airflow/.local/lib/python3.8/site-packages/airflow/models/taskinstance.py", line 433, in _execute_task
    result = execute_callable(context=context, **execute_callable_kwargs)
  File "/home/airflow/.local/lib/python3.8/site-packages/airflow/operators/python.py", line 199, in execute
    return_value = self.execute_callable()
  File "/home/airflow/.local/lib/python3.8/site-packages/airflow/operators/python.py", line 216, in execute_callable
    return self.python_callable(*self.op_args, **self.op_kwargs)
TypeError: write_to_database() missing 1 required positional argument: 'self'
[2023-12-23T13:40:51.698+0000] {taskinstance.py:1138} INFO - Marking task as UP_FOR_RETRY. dag_id=dag_to_dum_raw_data_to_postgres, task_id=load_raw_data_to_postgres, execution_date=20231223T134048, start_date=20231223T134051, end_date=20231223T134051
[2023-12-23T13:40:51.713+0000] {standard_task_runner.py:107} ERROR - Failed to execute job 1224 for task load_raw_data_to_postgres (write_to_database() missing 1 required positional argument: 'self'; 289)
[2023-12-23T13:40:51.738+0000] {local_task_job_runner.py:234} INFO - Task exited with return code 1
[2023-12-23T13:40:51.754+0000] {taskinstance.py:3281} INFO - 0 downstream tasks scheduled from follow-on schedule check
