[2023-12-23T13:50:54.814+0000] {taskinstance.py:1957} INFO - Dependencies all met for dep_context=non-requeueable deps ti=<TaskInstance: dag_to_dum_raw_data_to_postgres.load_raw_data_to_postgres manual__2023-12-23T13:40:48.232288+00:00 [queued]>
[2023-12-23T13:50:54.825+0000] {taskinstance.py:1957} INFO - Dependencies all met for dep_context=requeueable deps ti=<TaskInstance: dag_to_dum_raw_data_to_postgres.load_raw_data_to_postgres manual__2023-12-23T13:40:48.232288+00:00 [queued]>
[2023-12-23T13:50:54.826+0000] {taskinstance.py:2171} INFO - Starting attempt 3 of 6
[2023-12-23T13:50:54.993+0000] {taskinstance.py:2192} INFO - Executing <Task(PythonOperator): load_raw_data_to_postgres> on 2023-12-23 13:40:48.232288+00:00
[2023-12-23T13:50:54.999+0000] {standard_task_runner.py:60} INFO - Started process 510 to run task
[2023-12-23T13:50:55.004+0000] {standard_task_runner.py:87} INFO - Running: ['***', 'tasks', 'run', 'dag_to_dum_raw_data_to_postgres', 'load_raw_data_to_postgres', 'manual__2023-12-23T13:40:48.232288+00:00', '--job-id', '1250', '--raw', '--subdir', 'DAGS_FOLDER/dump_raw_data_to_postgres.py', '--cfg-path', '/tmp/tmpt0ht7cqi']
[2023-12-23T13:50:55.007+0000] {standard_task_runner.py:88} INFO - Job 1250: Subtask load_raw_data_to_postgres
[2023-12-23T13:50:55.065+0000] {task_command.py:423} INFO - Running <TaskInstance: dag_to_dum_raw_data_to_postgres.load_raw_data_to_postgres manual__2023-12-23T13:40:48.232288+00:00 [running]> on host 51dca2e3ed8e
[2023-12-23T13:50:55.156+0000] {taskinstance.py:2481} INFO - Exporting env vars: AIRFLOW_CTX_DAG_OWNER='10 academy' AIRFLOW_CTX_DAG_ID='dag_to_dum_raw_data_to_postgres' AIRFLOW_CTX_TASK_ID='load_raw_data_to_postgres' AIRFLOW_CTX_EXECUTION_DATE='2023-12-23T13:40:48.232288+00:00' AIRFLOW_CTX_TRY_NUMBER='3' AIRFLOW_CTX_DAG_RUN_ID='manual__2023-12-23T13:40:48.232288+00:00'
[2023-12-23T13:50:55.160+0000] {warnings.py:109} WARNING - /opt/***/dags/dump_raw_data_to_postgres.py:24: ParserWarning: Falling back to the 'python' engine because the 'c' engine does not support regex separators (separators > 1 char and different from '\s+' are interpreted as regex); you can avoid this warning by specifying engine='python'.
  df = pd.read_csv(file_path,index_col=False, delimiter='; ')

[2023-12-23T13:50:55.163+0000] {taskinstance.py:2699} ERROR - Task failed with exception
Traceback (most recent call last):
  File "/home/airflow/.local/lib/python3.8/site-packages/airflow/models/taskinstance.py", line 433, in _execute_task
    result = execute_callable(context=context, **execute_callable_kwargs)
  File "/home/airflow/.local/lib/python3.8/site-packages/airflow/operators/python.py", line 199, in execute
    return_value = self.execute_callable()
  File "/home/airflow/.local/lib/python3.8/site-packages/airflow/operators/python.py", line 216, in execute_callable
    return self.python_callable(*self.op_args, **self.op_kwargs)
  File "/opt/airflow/dags/dump_raw_data_to_postgres.py", line 24, in write_to_database
    df = pd.read_csv(file_path,index_col=False, delimiter='; ')
  File "/home/airflow/.local/lib/python3.8/site-packages/pandas/io/parsers/readers.py", line 912, in read_csv
    return _read(filepath_or_buffer, kwds)
  File "/home/airflow/.local/lib/python3.8/site-packages/pandas/io/parsers/readers.py", line 577, in _read
    parser = TextFileReader(filepath_or_buffer, **kwds)
  File "/home/airflow/.local/lib/python3.8/site-packages/pandas/io/parsers/readers.py", line 1407, in __init__
    self._engine = self._make_engine(f, self.engine)
  File "/home/airflow/.local/lib/python3.8/site-packages/pandas/io/parsers/readers.py", line 1661, in _make_engine
    self.handles = get_handle(
  File "/home/airflow/.local/lib/python3.8/site-packages/pandas/io/common.py", line 859, in get_handle
    handle = open(
FileNotFoundError: [Errno 2] No such file or directory: 'raw-data/20181024_d1_0830_0900.csv'
[2023-12-23T13:50:55.175+0000] {taskinstance.py:1138} INFO - Marking task as UP_FOR_RETRY. dag_id=dag_to_dum_raw_data_to_postgres, task_id=load_raw_data_to_postgres, execution_date=20231223T134048, start_date=20231223T135054, end_date=20231223T135055
[2023-12-23T13:50:55.192+0000] {standard_task_runner.py:107} ERROR - Failed to execute job 1250 for task load_raw_data_to_postgres ([Errno 2] No such file or directory: 'raw-data/20181024_d1_0830_0900.csv'; 510)
[2023-12-23T13:50:55.215+0000] {local_task_job_runner.py:234} INFO - Task exited with return code 1
[2023-12-23T13:50:55.285+0000] {taskinstance.py:3281} INFO - 0 downstream tasks scheduled from follow-on schedule check
