[2023-12-19T18:39:01.109+0000] {taskinstance.py:1957} INFO - Dependencies all met for dep_context=non-requeueable deps ti=<TaskInstance: load_data.load_data_task_one scheduled__2023-12-19T18:38:00+00:00 [queued]>
[2023-12-19T18:39:01.136+0000] {taskinstance.py:1957} INFO - Dependencies all met for dep_context=requeueable deps ti=<TaskInstance: load_data.load_data_task_one scheduled__2023-12-19T18:38:00+00:00 [queued]>
[2023-12-19T18:39:01.139+0000] {taskinstance.py:2171} INFO - Starting attempt 1 of 2
[2023-12-19T18:39:01.169+0000] {taskinstance.py:2192} INFO - Executing <Task(PythonOperator): load_data_task_one> on 2023-12-19 18:38:00+00:00
[2023-12-19T18:39:01.175+0000] {standard_task_runner.py:60} INFO - Started process 1309 to run task
[2023-12-19T18:39:01.182+0000] {standard_task_runner.py:87} INFO - Running: ['***', 'tasks', 'run', 'load_data', 'load_data_task_one', 'scheduled__2023-12-19T18:38:00+00:00', '--job-id', '169', '--raw', '--subdir', 'DAGS_FOLDER/load_data_dag.py', '--cfg-path', '/tmp/tmpaei055lf']
[2023-12-19T18:39:01.188+0000] {standard_task_runner.py:88} INFO - Job 169: Subtask load_data_task_one
[2023-12-19T18:39:01.263+0000] {task_command.py:423} INFO - Running <TaskInstance: load_data.load_data_task_one scheduled__2023-12-19T18:38:00+00:00 [running]> on host adf250ae6131
[2023-12-19T18:39:01.545+0000] {taskinstance.py:2481} INFO - Exporting env vars: AIRFLOW_CTX_DAG_OWNER='Mickiyas' AIRFLOW_CTX_DAG_ID='load_data' AIRFLOW_CTX_TASK_ID='load_data_task_one' AIRFLOW_CTX_EXECUTION_DATE='2023-12-19T18:38:00+00:00' AIRFLOW_CTX_TRY_NUMBER='1' AIRFLOW_CTX_DAG_RUN_ID='scheduled__2023-12-19T18:38:00+00:00'
[2023-12-19T18:39:01.548+0000] {taskinstance.py:2699} ERROR - Task failed with exception
Traceback (most recent call last):
  File "/home/airflow/.local/lib/python3.8/site-packages/airflow/models/taskinstance.py", line 433, in _execute_task
    result = execute_callable(context=context, **execute_callable_kwargs)
  File "/home/airflow/.local/lib/python3.8/site-packages/airflow/operators/python.py", line 199, in execute
    return_value = self.execute_callable()
  File "/home/airflow/.local/lib/python3.8/site-packages/airflow/operators/python.py", line 216, in execute_callable
    return self.python_callable(*self.op_args, **self.op_kwargs)
  File "/opt/airflow/dags/load_data_dag.py", line 17, in load_data
    df = pd.read_csv(file_path)
  File "/home/airflow/.local/lib/python3.8/site-packages/pandas/io/parsers/readers.py", line 912, in read_csv
    return _read(filepath_or_buffer, kwds)
  File "/home/airflow/.local/lib/python3.8/site-packages/pandas/io/parsers/readers.py", line 577, in _read
    parser = TextFileReader(filepath_or_buffer, **kwds)
  File "/home/airflow/.local/lib/python3.8/site-packages/pandas/io/parsers/readers.py", line 1407, in __init__
    self._engine = self._make_engine(f, self.engine)
  File "/home/airflow/.local/lib/python3.8/site-packages/pandas/io/parsers/readers.py", line 1661, in _make_engine
    self.handles = get_handle(
  File "/home/airflow/.local/lib/python3.8/site-packages/pandas/io/common.py", line 859, in get_handle
    handle = open(
FileNotFoundError: [Errno 2] No such file or directory: '../raw-data/20181024_d1_0830_0900.csv'
[2023-12-19T18:39:01.558+0000] {taskinstance.py:1138} INFO - Marking task as UP_FOR_RETRY. dag_id=load_data, task_id=load_data_task_one, execution_date=20231219T183800, start_date=20231219T183901, end_date=20231219T183901
[2023-12-19T18:39:01.574+0000] {standard_task_runner.py:107} ERROR - Failed to execute job 169 for task load_data_task_one ([Errno 2] No such file or directory: '../raw-data/20181024_d1_0830_0900.csv'; 1309)
[2023-12-19T18:39:01.598+0000] {local_task_job_runner.py:234} INFO - Task exited with return code 1
[2023-12-19T18:39:01.616+0000] {taskinstance.py:3281} INFO - 0 downstream tasks scheduled from follow-on schedule check
